[2025-04-02T20:05:01.411+0000] {taskinstance.py:1956} INFO - Dependencies all met for dep_context=non-requeueable deps ti=<TaskInstance: Weather_Proj.Write_data_in_kafka manual__2025-04-02T20:03:57.380111+00:00 [queued]>
[2025-04-02T20:05:01.425+0000] {taskinstance.py:1956} INFO - Dependencies all met for dep_context=requeueable deps ti=<TaskInstance: Weather_Proj.Write_data_in_kafka manual__2025-04-02T20:03:57.380111+00:00 [queued]>
[2025-04-02T20:05:01.426+0000] {taskinstance.py:2170} INFO - Starting attempt 1 of 1
[2025-04-02T20:05:01.443+0000] {taskinstance.py:2191} INFO - Executing <Task(PythonOperator): Write_data_in_kafka> on 2025-04-02 20:03:57.380111+00:00
[2025-04-02T20:05:01.448+0000] {standard_task_runner.py:60} INFO - Started process 1880 to run task
[2025-04-02T20:05:01.448+0000] {clientserver.py:543} INFO - Closing down clientserver connection
[2025-04-02T20:05:01.454+0000] {standard_task_runner.py:87} INFO - Running: ['***', 'tasks', 'run', 'Weather_Proj', 'Write_data_in_kafka', 'manual__2025-04-02T20:03:57.380111+00:00', '--job-id', '19', '--raw', '--subdir', 'DAGS_FOLDER/Project_tasks.py', '--cfg-path', '/tmp/tmpiqajjsse']
[2025-04-02T20:05:01.455+0000] {standard_task_runner.py:88} INFO - Job 19: Subtask Write_data_in_kafka
[2025-04-02T20:05:01.506+0000] {task_command.py:423} INFO - Running <TaskInstance: Weather_Proj.Write_data_in_kafka manual__2025-04-02T20:03:57.380111+00:00 [running]> on host 0d0dab2febfc
[2025-04-02T20:05:01.578+0000] {taskinstance.py:2480} INFO - Exporting env vars: AIRFLOW_CTX_DAG_OWNER='***' AIRFLOW_CTX_DAG_ID='Weather_Proj' AIRFLOW_CTX_TASK_ID='Write_data_in_kafka' AIRFLOW_CTX_EXECUTION_DATE='2025-04-02T20:03:57.380111+00:00' AIRFLOW_CTX_TRY_NUMBER='1' AIRFLOW_CTX_DAG_RUN_ID='manual__2025-04-02T20:03:57.380111+00:00'
[2025-04-02T20:09:39.165+0000] {local_task_job_runner.py:302} WARNING - State of this instance has been externally set to None. Terminating instance.
[2025-04-02T20:09:39.169+0000] {process_utils.py:131} INFO - Sending 15 to group 1880. PIDs of all processes in the group: [1880]
[2025-04-02T20:09:39.170+0000] {process_utils.py:86} INFO - Sending the signal 15 to group 1880
[2025-04-02T20:10:01.640+0000] {taskinstance.py:2450} ERROR - Received SIGTERM. Terminating subprocesses.
[2025-04-02T20:10:01.651+0000] {taskinstance.py:2698} ERROR - Task failed with exception
Traceback (most recent call last):
  File "/home/airflow/.local/lib/python3.10/site-packages/airflow/models/taskinstance.py", line 433, in _execute_task
    result = execute_callable(context=context, **execute_callable_kwargs)
  File "/home/airflow/.local/lib/python3.10/site-packages/airflow/operators/python.py", line 199, in execute
    return_value = self.execute_callable()
  File "/home/airflow/.local/lib/python3.10/site-packages/airflow/operators/python.py", line 216, in execute_callable
    return self.python_callable(*self.op_args, **self.op_kwargs)
  File "/opt/airflow/dags/WeatherScripts/producer.py", line 20, in produceTopic
    producer.flush()
  File "/home/airflow/.local/lib/python3.10/site-packages/airflow/models/taskinstance.py", line 2452, in signal_handler
    raise AirflowException("Task received SIGTERM signal")
airflow.exceptions.AirflowException: Task received SIGTERM signal
[2025-04-02T20:10:01.659+0000] {taskinstance.py:1138} INFO - Marking task as FAILED. dag_id=Weather_Proj, task_id=Write_data_in_kafka, execution_date=20250402T200357, start_date=20250402T200501, end_date=20250402T201001
[2025-04-02T20:10:01.670+0000] {standard_task_runner.py:107} ERROR - Failed to execute job 19 for task Write_data_in_kafka ((psycopg2.errors.ForeignKeyViolation) insert or update on table "task_fail" violates foreign key constraint "task_fail_ti_fkey"
DETAIL:  Key (dag_id, task_id, run_id, map_index)=(Weather_Proj, Write_data_in_kafka, manual__2025-04-02T20:03:57.380111+00:00, -1) is not present in table "task_instance".

[SQL: INSERT INTO task_fail (task_id, dag_id, run_id, map_index, start_date, end_date, duration) VALUES (%(task_id)s, %(dag_id)s, %(run_id)s, %(map_index)s, %(start_date)s, %(end_date)s, %(duration)s) RETURNING task_fail.id]
[parameters: {'task_id': 'Write_data_in_kafka', 'dag_id': 'Weather_Proj', 'run_id': 'manual__2025-04-02T20:03:57.380111+00:00', 'map_index': -1, 'start_date': datetime.datetime(2025, 4, 2, 20, 5, 1, 412001, tzinfo=Timezone('UTC')), 'end_date': datetime.datetime(2025, 4, 2, 20, 10, 1, 658668, tzinfo=Timezone('UTC')), 'duration': 300}]
(Background on this error at: https://sqlalche.me/e/14/gkpj); 1880)
[2025-04-02T20:10:01.686+0000] {process_utils.py:79} INFO - Process psutil.Process(pid=1880, status='terminated', exitcode=1, started='20:05:00') (1880) terminated with exit code 1
