[2025-04-02T19:46:29.147+0000] {taskinstance.py:1956} INFO - Dependencies all met for dep_context=non-requeueable deps ti=<TaskInstance: Weather_Proj.Produce_data manual__2025-04-02T19:46:22.742383+00:00 [queued]>
[2025-04-02T19:46:29.155+0000] {taskinstance.py:1956} INFO - Dependencies all met for dep_context=requeueable deps ti=<TaskInstance: Weather_Proj.Produce_data manual__2025-04-02T19:46:22.742383+00:00 [queued]>
[2025-04-02T19:46:29.156+0000] {taskinstance.py:2170} INFO - Starting attempt 1 of 1
[2025-04-02T19:46:29.171+0000] {taskinstance.py:2191} INFO - Executing <Task(PythonOperator): Produce_data> on 2025-04-02 19:46:22.742383+00:00
[2025-04-02T19:46:29.177+0000] {standard_task_runner.py:60} INFO - Started process 1311 to run task
[2025-04-02T19:46:29.177+0000] {clientserver.py:543} INFO - Closing down clientserver connection
[2025-04-02T19:46:29.182+0000] {standard_task_runner.py:87} INFO - Running: ['***', 'tasks', 'run', 'Weather_Proj', 'Produce_data', 'manual__2025-04-02T19:46:22.742383+00:00', '--job-id', '6', '--raw', '--subdir', 'DAGS_FOLDER/Project_tasks.py', '--cfg-path', '/tmp/tmppy5l_fwu']
[2025-04-02T19:46:29.183+0000] {standard_task_runner.py:88} INFO - Job 6: Subtask Produce_data
[2025-04-02T19:46:29.233+0000] {task_command.py:423} INFO - Running <TaskInstance: Weather_Proj.Produce_data manual__2025-04-02T19:46:22.742383+00:00 [running]> on host 12651c21963e
[2025-04-02T19:46:29.297+0000] {taskinstance.py:2480} INFO - Exporting env vars: AIRFLOW_CTX_DAG_OWNER='***' AIRFLOW_CTX_DAG_ID='Weather_Proj' AIRFLOW_CTX_TASK_ID='Produce_data' AIRFLOW_CTX_EXECUTION_DATE='2025-04-02T19:46:22.742383+00:00' AIRFLOW_CTX_TRY_NUMBER='1' AIRFLOW_CTX_DAG_RUN_ID='manual__2025-04-02T19:46:22.742383+00:00'
[2025-04-02T19:47:34.848+0000] {taskinstance.py:2698} ERROR - Task failed with exception
Traceback (most recent call last):
  File "/home/airflow/.local/lib/python3.10/site-packages/urllib3/connection.py", line 203, in _new_conn
    sock = connection.create_connection(
  File "/home/airflow/.local/lib/python3.10/site-packages/urllib3/util/connection.py", line 85, in create_connection
    raise err
  File "/home/airflow/.local/lib/python3.10/site-packages/urllib3/util/connection.py", line 73, in create_connection
    sock.connect(sa)
ConnectionRefusedError: [Errno 111] Connection refused

The above exception was the direct cause of the following exception:

Traceback (most recent call last):
  File "/home/airflow/.local/lib/python3.10/site-packages/urllib3/connectionpool.py", line 791, in urlopen
    response = self._make_request(
  File "/home/airflow/.local/lib/python3.10/site-packages/urllib3/connectionpool.py", line 492, in _make_request
    raise new_e
  File "/home/airflow/.local/lib/python3.10/site-packages/urllib3/connectionpool.py", line 468, in _make_request
    self._validate_conn(conn)
  File "/home/airflow/.local/lib/python3.10/site-packages/urllib3/connectionpool.py", line 1097, in _validate_conn
    conn.connect()
  File "/home/airflow/.local/lib/python3.10/site-packages/urllib3/connection.py", line 611, in connect
    self.sock = sock = self._new_conn()
  File "/home/airflow/.local/lib/python3.10/site-packages/urllib3/connection.py", line 218, in _new_conn
    raise NewConnectionError(
urllib3.exceptions.NewConnectionError: <urllib3.connection.HTTPSConnection object at 0x7f6103b89570>: Failed to establish a new connection: [Errno 111] Connection refused

The above exception was the direct cause of the following exception:

Traceback (most recent call last):
  File "/home/airflow/.local/lib/python3.10/site-packages/requests/adapters.py", line 486, in send
    resp = conn.urlopen(
  File "/home/airflow/.local/lib/python3.10/site-packages/urllib3/connectionpool.py", line 845, in urlopen
    retries = retries.increment(
  File "/home/airflow/.local/lib/python3.10/site-packages/urllib3/util/retry.py", line 515, in increment
    raise MaxRetryError(_pool, url, reason) from reason  # type: ignore[arg-type]
urllib3.exceptions.MaxRetryError: HTTPSConnectionPool(host='api.openweathermap.org', port=443): Max retries exceeded with url: /data/2.5/weather?q=Giza,EG&units=metric&appid=e6af95748c4e865b15b05a5f3014e14d (Caused by NewConnectionError('<urllib3.connection.HTTPSConnection object at 0x7f6103b89570>: Failed to establish a new connection: [Errno 111] Connection refused'))

During handling of the above exception, another exception occurred:

Traceback (most recent call last):
  File "/home/airflow/.local/lib/python3.10/site-packages/airflow/models/taskinstance.py", line 433, in _execute_task
    result = execute_callable(context=context, **execute_callable_kwargs)
  File "/home/airflow/.local/lib/python3.10/site-packages/airflow/operators/python.py", line 199, in execute
    return_value = self.execute_callable()
  File "/home/airflow/.local/lib/python3.10/site-packages/airflow/operators/python.py", line 216, in execute_callable
    return self.python_callable(*self.op_args, **self.op_kwargs)
  File "/opt/airflow/dags/WeatherScripts/API_Call.py", line 19, in apiCall
    response = requests.get(url=f"https://api.openweathermap.org/data/2.5/weather?q={city},{country}&units={untis}&appid={api_key}")
  File "/home/airflow/.local/lib/python3.10/site-packages/requests/api.py", line 73, in get
    return request("get", url, params=params, **kwargs)
  File "/home/airflow/.local/lib/python3.10/site-packages/requests/api.py", line 59, in request
    return session.request(method=method, url=url, **kwargs)
  File "/home/airflow/.local/lib/python3.10/site-packages/requests/sessions.py", line 589, in request
    resp = self.send(prep, **send_kwargs)
  File "/home/airflow/.local/lib/python3.10/site-packages/requests/sessions.py", line 703, in send
    r = adapter.send(request, **kwargs)
  File "/home/airflow/.local/lib/python3.10/site-packages/requests/adapters.py", line 519, in send
    raise ConnectionError(e, request=request)
requests.exceptions.ConnectionError: HTTPSConnectionPool(host='api.openweathermap.org', port=443): Max retries exceeded with url: /data/2.5/weather?q=Giza,EG&units=metric&appid=e6af95748c4e865b15b05a5f3014e14d (Caused by NewConnectionError('<urllib3.connection.HTTPSConnection object at 0x7f6103b89570>: Failed to establish a new connection: [Errno 111] Connection refused'))
[2025-04-02T19:47:34.864+0000] {taskinstance.py:1138} INFO - Marking task as FAILED. dag_id=Weather_Proj, task_id=Produce_data, execution_date=20250402T194622, start_date=20250402T194629, end_date=20250402T194734
[2025-04-02T19:47:34.874+0000] {standard_task_runner.py:107} ERROR - Failed to execute job 6 for task Produce_data (HTTPSConnectionPool(host='api.openweathermap.org', port=443): Max retries exceeded with url: /data/2.5/weather?q=Giza,EG&units=metric&appid=e6af95748c4e865b15b05a5f3014e14d (Caused by NewConnectionError('<urllib3.connection.HTTPSConnection object at 0x7f6103b89570>: Failed to establish a new connection: [Errno 111] Connection refused')); 1311)
[2025-04-02T19:47:34.899+0000] {local_task_job_runner.py:234} INFO - Task exited with return code 1
[2025-04-02T19:47:34.927+0000] {taskinstance.py:3280} INFO - 0 downstream tasks scheduled from follow-on schedule check
