[2025-04-02T20:02:20.035+0000] {taskinstance.py:1956} INFO - Dependencies all met for dep_context=non-requeueable deps ti=<TaskInstance: Weather_Proj.Write_data_in_kafka manual__2025-04-02T20:01:49.595840+00:00 [queued]>
[2025-04-02T20:02:20.041+0000] {taskinstance.py:1956} INFO - Dependencies all met for dep_context=requeueable deps ti=<TaskInstance: Weather_Proj.Write_data_in_kafka manual__2025-04-02T20:01:49.595840+00:00 [queued]>
[2025-04-02T20:02:20.041+0000] {taskinstance.py:2170} INFO - Starting attempt 1 of 1
[2025-04-02T20:02:20.053+0000] {taskinstance.py:2191} INFO - Executing <Task(PythonOperator): Write_data_in_kafka> on 2025-04-02 20:01:49.595840+00:00
[2025-04-02T20:02:20.057+0000] {standard_task_runner.py:60} INFO - Started process 1294 to run task
[2025-04-02T20:02:20.057+0000] {clientserver.py:543} INFO - Closing down clientserver connection
[2025-04-02T20:02:20.064+0000] {standard_task_runner.py:87} INFO - Running: ['***', 'tasks', 'run', 'Weather_Proj', 'Write_data_in_kafka', 'manual__2025-04-02T20:01:49.595840+00:00', '--job-id', '17', '--raw', '--subdir', 'DAGS_FOLDER/Project_tasks.py', '--cfg-path', '/tmp/tmpk0hl7c5s']
[2025-04-02T20:02:20.066+0000] {standard_task_runner.py:88} INFO - Job 17: Subtask Write_data_in_kafka
[2025-04-02T20:02:20.114+0000] {task_command.py:423} INFO - Running <TaskInstance: Weather_Proj.Write_data_in_kafka manual__2025-04-02T20:01:49.595840+00:00 [running]> on host 0d0dab2febfc
[2025-04-02T20:02:20.188+0000] {taskinstance.py:2480} INFO - Exporting env vars: AIRFLOW_CTX_DAG_OWNER='***' AIRFLOW_CTX_DAG_ID='Weather_Proj' AIRFLOW_CTX_TASK_ID='Write_data_in_kafka' AIRFLOW_CTX_EXECUTION_DATE='2025-04-02T20:01:49.595840+00:00' AIRFLOW_CTX_TRY_NUMBER='1' AIRFLOW_CTX_DAG_RUN_ID='manual__2025-04-02T20:01:49.595840+00:00'
[2025-04-02T20:02:20.205+0000] {taskinstance.py:2698} ERROR - Task failed with exception
Traceback (most recent call last):
  File "/home/airflow/.local/lib/python3.10/site-packages/airflow/models/taskinstance.py", line 433, in _execute_task
    result = execute_callable(context=context, **execute_callable_kwargs)
  File "/home/airflow/.local/lib/python3.10/site-packages/airflow/operators/python.py", line 199, in execute
    return_value = self.execute_callable()
  File "/home/airflow/.local/lib/python3.10/site-packages/airflow/operators/python.py", line 216, in execute_callable
    return self.python_callable(*self.op_args, **self.op_kwargs)
  File "/opt/airflow/dags/WeatherScripts/producer.py", line 11, in produceTopic
    with open(f"{file_name}", 'r',encoding="utf-8") as file:
FileNotFoundError: [Errno 2] No such file or directory: '/opt/airflow/dags/WeatherScripts/data.json'
[2025-04-02T20:02:20.215+0000] {taskinstance.py:1138} INFO - Marking task as FAILED. dag_id=Weather_Proj, task_id=Write_data_in_kafka, execution_date=20250402T200149, start_date=20250402T200220, end_date=20250402T200220
[2025-04-02T20:02:20.224+0000] {standard_task_runner.py:107} ERROR - Failed to execute job 17 for task Write_data_in_kafka ([Errno 2] No such file or directory: '/opt/airflow/dags/WeatherScripts/data.json'; 1294)
[2025-04-02T20:02:20.233+0000] {local_task_job_runner.py:234} INFO - Task exited with return code 1
[2025-04-02T20:02:20.255+0000] {taskinstance.py:3280} INFO - 0 downstream tasks scheduled from follow-on schedule check
