[2025-04-02T20:40:07.408+0000] {taskinstance.py:1956} INFO - Dependencies all met for dep_context=non-requeueable deps ti=<TaskInstance: Weather_Proj.Produce_data scheduled__2025-04-02T20:00:00+00:00 [queued]>
[2025-04-02T20:40:07.415+0000] {taskinstance.py:1956} INFO - Dependencies all met for dep_context=requeueable deps ti=<TaskInstance: Weather_Proj.Produce_data scheduled__2025-04-02T20:00:00+00:00 [queued]>
[2025-04-02T20:40:07.416+0000] {taskinstance.py:2170} INFO - Starting attempt 1 of 1
[2025-04-02T20:40:07.428+0000] {taskinstance.py:2191} INFO - Executing <Task(PythonOperator): Produce_data> on 2025-04-02 20:00:00+00:00
[2025-04-02T20:40:07.434+0000] {clientserver.py:543} INFO - Closing down clientserver connection
[2025-04-02T20:40:07.434+0000] {standard_task_runner.py:60} INFO - Started process 2116 to run task
[2025-04-02T20:40:07.439+0000] {standard_task_runner.py:87} INFO - Running: ['***', 'tasks', 'run', 'Weather_Proj', 'Produce_data', 'scheduled__2025-04-02T20:00:00+00:00', '--job-id', '28', '--raw', '--subdir', 'DAGS_FOLDER/Project_tasks.py', '--cfg-path', '/tmp/tmpmunygox0']
[2025-04-02T20:40:07.441+0000] {standard_task_runner.py:88} INFO - Job 28: Subtask Produce_data
[2025-04-02T20:40:07.489+0000] {task_command.py:423} INFO - Running <TaskInstance: Weather_Proj.Produce_data scheduled__2025-04-02T20:00:00+00:00 [running]> on host 34d96960033d
[2025-04-02T20:40:07.557+0000] {taskinstance.py:2480} INFO - Exporting env vars: AIRFLOW_CTX_DAG_OWNER='***' AIRFLOW_CTX_DAG_ID='Weather_Proj' AIRFLOW_CTX_TASK_ID='Produce_data' AIRFLOW_CTX_EXECUTION_DATE='2025-04-02T20:00:00+00:00' AIRFLOW_CTX_TRY_NUMBER='1' AIRFLOW_CTX_DAG_RUN_ID='scheduled__2025-04-02T20:00:00+00:00'
[2025-04-02T20:40:27.583+0000] {job.py:213} ERROR - Job heartbeat got an exception
Traceback (most recent call last):
  File "/home/airflow/.local/lib/python3.10/site-packages/sqlalchemy/engine/base.py", line 3371, in _wrap_pool_connect
    return fn()
  File "/home/airflow/.local/lib/python3.10/site-packages/sqlalchemy/pool/base.py", line 327, in connect
    return _ConnectionFairy._checkout(self)
  File "/home/airflow/.local/lib/python3.10/site-packages/sqlalchemy/pool/base.py", line 894, in _checkout
    fairy = _ConnectionRecord.checkout(pool)
  File "/home/airflow/.local/lib/python3.10/site-packages/sqlalchemy/pool/base.py", line 493, in checkout
    rec = pool._do_get()
  File "/home/airflow/.local/lib/python3.10/site-packages/sqlalchemy/pool/impl.py", line 256, in _do_get
    return self._create_connection()
  File "/home/airflow/.local/lib/python3.10/site-packages/sqlalchemy/pool/base.py", line 273, in _create_connection
    return _ConnectionRecord(self)
  File "/home/airflow/.local/lib/python3.10/site-packages/sqlalchemy/pool/base.py", line 388, in __init__
    self.__connect()
  File "/home/airflow/.local/lib/python3.10/site-packages/sqlalchemy/pool/base.py", line 690, in __connect
    with util.safe_reraise():
  File "/home/airflow/.local/lib/python3.10/site-packages/sqlalchemy/util/langhelpers.py", line 70, in __exit__
    compat.raise_(
  File "/home/airflow/.local/lib/python3.10/site-packages/sqlalchemy/util/compat.py", line 211, in raise_
    raise exception
  File "/home/airflow/.local/lib/python3.10/site-packages/sqlalchemy/pool/base.py", line 686, in __connect
    self.dbapi_connection = connection = pool._invoke_creator(self)
  File "/home/airflow/.local/lib/python3.10/site-packages/sqlalchemy/engine/create.py", line 574, in connect
    return dialect.connect(*cargs, **cparams)
  File "/home/airflow/.local/lib/python3.10/site-packages/sqlalchemy/engine/default.py", line 598, in connect
    return self.dbapi.connect(*cargs, **cparams)
  File "/home/airflow/.local/lib/python3.10/site-packages/psycopg2/__init__.py", line 122, in connect
    conn = _connect(dsn, connection_factory=connection_factory, **kwasync)
psycopg2.OperationalError: could not translate host name "postgres" to address: Temporary failure in name resolution


The above exception was the direct cause of the following exception:

Traceback (most recent call last):
  File "/home/airflow/.local/lib/python3.10/site-packages/airflow/jobs/job.py", line 187, in heartbeat
    self._merge_from(Job._fetch_from_db(self, session))
  File "/home/airflow/.local/lib/python3.10/site-packages/airflow/api_internal/internal_api_call.py", line 114, in wrapper
    return func(*args, **kwargs)
  File "/home/airflow/.local/lib/python3.10/site-packages/airflow/utils/session.py", line 76, in wrapper
    return func(*args, **kwargs)
  File "/home/airflow/.local/lib/python3.10/site-packages/airflow/jobs/job.py", line 308, in _fetch_from_db
    session.merge(job)
  File "/home/airflow/.local/lib/python3.10/site-packages/sqlalchemy/orm/session.py", line 3056, in merge
    return self._merge(
  File "/home/airflow/.local/lib/python3.10/site-packages/sqlalchemy/orm/session.py", line 3136, in _merge
    merged = self.get(
  File "/home/airflow/.local/lib/python3.10/site-packages/sqlalchemy/orm/session.py", line 2853, in get
    return self._get_impl(
  File "/home/airflow/.local/lib/python3.10/site-packages/sqlalchemy/orm/session.py", line 2975, in _get_impl
    return db_load_fn(
  File "/home/airflow/.local/lib/python3.10/site-packages/sqlalchemy/orm/loading.py", line 530, in load_on_pk_identity
    session.execute(
  File "/home/airflow/.local/lib/python3.10/site-packages/sqlalchemy/orm/session.py", line 1716, in execute
    conn = self._connection_for_bind(bind)
  File "/home/airflow/.local/lib/python3.10/site-packages/sqlalchemy/orm/session.py", line 1555, in _connection_for_bind
    return self._transaction._connection_for_bind(
  File "/home/airflow/.local/lib/python3.10/site-packages/sqlalchemy/orm/session.py", line 750, in _connection_for_bind
    conn = bind.connect()
  File "/home/airflow/.local/lib/python3.10/site-packages/sqlalchemy/future/engine.py", line 412, in connect
    return super(Engine, self).connect()
  File "/home/airflow/.local/lib/python3.10/site-packages/sqlalchemy/engine/base.py", line 3325, in connect
    return self._connection_cls(self, close_with_result=close_with_result)
  File "/home/airflow/.local/lib/python3.10/site-packages/sqlalchemy/engine/base.py", line 96, in __init__
    else engine.raw_connection()
  File "/home/airflow/.local/lib/python3.10/site-packages/sqlalchemy/engine/base.py", line 3404, in raw_connection
    return self._wrap_pool_connect(self.pool.connect, _connection)
  File "/home/airflow/.local/lib/python3.10/site-packages/sqlalchemy/engine/base.py", line 3374, in _wrap_pool_connect
    Connection._handle_dbapi_exception_noconnection(
  File "/home/airflow/.local/lib/python3.10/site-packages/sqlalchemy/engine/base.py", line 2208, in _handle_dbapi_exception_noconnection
    util.raise_(
  File "/home/airflow/.local/lib/python3.10/site-packages/sqlalchemy/util/compat.py", line 211, in raise_
    raise exception
  File "/home/airflow/.local/lib/python3.10/site-packages/sqlalchemy/engine/base.py", line 3371, in _wrap_pool_connect
    return fn()
  File "/home/airflow/.local/lib/python3.10/site-packages/sqlalchemy/pool/base.py", line 327, in connect
    return _ConnectionFairy._checkout(self)
  File "/home/airflow/.local/lib/python3.10/site-packages/sqlalchemy/pool/base.py", line 894, in _checkout
    fairy = _ConnectionRecord.checkout(pool)
  File "/home/airflow/.local/lib/python3.10/site-packages/sqlalchemy/pool/base.py", line 493, in checkout
    rec = pool._do_get()
  File "/home/airflow/.local/lib/python3.10/site-packages/sqlalchemy/pool/impl.py", line 256, in _do_get
    return self._create_connection()
  File "/home/airflow/.local/lib/python3.10/site-packages/sqlalchemy/pool/base.py", line 273, in _create_connection
    return _ConnectionRecord(self)
  File "/home/airflow/.local/lib/python3.10/site-packages/sqlalchemy/pool/base.py", line 388, in __init__
    self.__connect()
  File "/home/airflow/.local/lib/python3.10/site-packages/sqlalchemy/pool/base.py", line 690, in __connect
    with util.safe_reraise():
  File "/home/airflow/.local/lib/python3.10/site-packages/sqlalchemy/util/langhelpers.py", line 70, in __exit__
    compat.raise_(
  File "/home/airflow/.local/lib/python3.10/site-packages/sqlalchemy/util/compat.py", line 211, in raise_
    raise exception
  File "/home/airflow/.local/lib/python3.10/site-packages/sqlalchemy/pool/base.py", line 686, in __connect
    self.dbapi_connection = connection = pool._invoke_creator(self)
  File "/home/airflow/.local/lib/python3.10/site-packages/sqlalchemy/engine/create.py", line 574, in connect
    return dialect.connect(*cargs, **cparams)
  File "/home/airflow/.local/lib/python3.10/site-packages/sqlalchemy/engine/default.py", line 598, in connect
    return self.dbapi.connect(*cargs, **cparams)
  File "/home/airflow/.local/lib/python3.10/site-packages/psycopg2/__init__.py", line 122, in connect
    conn = _connect(dsn, connection_factory=connection_factory, **kwasync)
sqlalchemy.exc.OperationalError: (psycopg2.OperationalError) could not translate host name "postgres" to address: Temporary failure in name resolution

(Background on this error at: https://sqlalche.me/e/14/e3q8)
[2025-04-02T20:40:27.712+0000] {job.py:221} ERROR - Job heartbeat failed with error. Scheduler is in unhealthy state
[2025-04-02T20:40:58.872+0000] {logging_mixin.py:188} INFO - Data successfully written to 'data.json'.
[2025-04-02T20:40:58.876+0000] {python.py:201} INFO - Done. Returned value was: None
[2025-04-02T20:40:58.885+0000] {taskinstance.py:1138} INFO - Marking task as SUCCESS. dag_id=Weather_Proj, task_id=Produce_data, execution_date=20250402T200000, start_date=20250402T204007, end_date=20250402T204058
[2025-04-02T20:40:58.908+0000] {local_task_job_runner.py:234} INFO - Task exited with return code 0
[2025-04-02T20:40:58.925+0000] {taskinstance.py:3280} INFO - 1 downstream tasks scheduled from follow-on schedule check
[2025-04-02T20:43:24.388+0000] {taskinstance.py:1956} INFO - Dependencies all met for dep_context=non-requeueable deps ti=<TaskInstance: Weather_Proj.Produce_data scheduled__2025-04-02T20:00:00+00:00 [queued]>
[2025-04-02T20:43:24.394+0000] {taskinstance.py:1956} INFO - Dependencies all met for dep_context=requeueable deps ti=<TaskInstance: Weather_Proj.Produce_data scheduled__2025-04-02T20:00:00+00:00 [queued]>
[2025-04-02T20:43:24.394+0000] {taskinstance.py:2170} INFO - Starting attempt 1 of 1
[2025-04-02T20:43:24.408+0000] {taskinstance.py:2191} INFO - Executing <Task(PythonOperator): Produce_data> on 2025-04-02 20:00:00+00:00
[2025-04-02T20:43:24.411+0000] {clientserver.py:543} INFO - Closing down clientserver connection
[2025-04-02T20:43:24.411+0000] {standard_task_runner.py:60} INFO - Started process 2788 to run task
[2025-04-02T20:43:24.417+0000] {standard_task_runner.py:87} INFO - Running: ['***', 'tasks', 'run', 'Weather_Proj', 'Produce_data', 'scheduled__2025-04-02T20:00:00+00:00', '--job-id', '30', '--raw', '--subdir', 'DAGS_FOLDER/Project_tasks.py', '--cfg-path', '/tmp/tmp9lxzao5e']
[2025-04-02T20:43:24.418+0000] {standard_task_runner.py:88} INFO - Job 30: Subtask Produce_data
[2025-04-02T20:43:24.459+0000] {task_command.py:423} INFO - Running <TaskInstance: Weather_Proj.Produce_data scheduled__2025-04-02T20:00:00+00:00 [running]> on host 34d96960033d
[2025-04-02T20:43:24.523+0000] {taskinstance.py:2480} INFO - Exporting env vars: AIRFLOW_CTX_DAG_OWNER='***' AIRFLOW_CTX_DAG_ID='Weather_Proj' AIRFLOW_CTX_TASK_ID='Produce_data' AIRFLOW_CTX_EXECUTION_DATE='2025-04-02T20:00:00+00:00' AIRFLOW_CTX_TRY_NUMBER='1' AIRFLOW_CTX_DAG_RUN_ID='scheduled__2025-04-02T20:00:00+00:00'
[2025-04-02T20:43:55.514+0000] {logging_mixin.py:188} INFO - Data successfully written to 'data.json'.
[2025-04-02T20:43:55.516+0000] {python.py:201} INFO - Done. Returned value was: None
[2025-04-02T20:43:55.525+0000] {taskinstance.py:1138} INFO - Marking task as SUCCESS. dag_id=Weather_Proj, task_id=Produce_data, execution_date=20250402T200000, start_date=20250402T204324, end_date=20250402T204355
[2025-04-02T20:43:55.564+0000] {local_task_job_runner.py:234} INFO - Task exited with return code 0
[2025-04-02T20:43:55.586+0000] {taskinstance.py:3280} INFO - 1 downstream tasks scheduled from follow-on schedule check
