[2025-04-04T12:52:50.351+0000] {taskinstance.py:1956} INFO - Dependencies all met for dep_context=non-requeueable deps ti=<TaskInstance: Weather_Proj.Spark_Processing manual__2025-04-04T12:52:09.811938+00:00 [queued]>
[2025-04-04T12:52:50.358+0000] {taskinstance.py:1956} INFO - Dependencies all met for dep_context=requeueable deps ti=<TaskInstance: Weather_Proj.Spark_Processing manual__2025-04-04T12:52:09.811938+00:00 [queued]>
[2025-04-04T12:52:50.359+0000] {taskinstance.py:2170} INFO - Starting attempt 1 of 1
[2025-04-04T12:52:50.370+0000] {taskinstance.py:2191} INFO - Executing <Task(PythonOperator): Spark_Processing> on 2025-04-04 12:52:09.811938+00:00
[2025-04-04T12:52:50.374+0000] {standard_task_runner.py:60} INFO - Started process 3397 to run task
[2025-04-04T12:52:50.377+0000] {standard_task_runner.py:87} INFO - Running: ['***', 'tasks', 'run', 'Weather_Proj', 'Spark_Processing', 'manual__2025-04-04T12:52:09.811938+00:00', '--job-id', '180', '--raw', '--subdir', 'DAGS_FOLDER/Project_tasks.py', '--cfg-path', '/tmp/tmpiw7ky_do']
[2025-04-04T12:52:50.379+0000] {standard_task_runner.py:88} INFO - Job 180: Subtask Spark_Processing
[2025-04-04T12:52:50.416+0000] {task_command.py:423} INFO - Running <TaskInstance: Weather_Proj.Spark_Processing manual__2025-04-04T12:52:09.811938+00:00 [running]> on host 7fc40170f80d
[2025-04-04T12:52:50.480+0000] {taskinstance.py:2480} INFO - Exporting env vars: AIRFLOW_CTX_DAG_OWNER='***' AIRFLOW_CTX_DAG_ID='Weather_Proj' AIRFLOW_CTX_TASK_ID='Spark_Processing' AIRFLOW_CTX_EXECUTION_DATE='2025-04-04T12:52:09.811938+00:00' AIRFLOW_CTX_TRY_NUMBER='1' AIRFLOW_CTX_DAG_RUN_ID='manual__2025-04-04T12:52:09.811938+00:00'
[2025-04-04T12:52:56.098+0000] {taskinstance.py:2698} ERROR - Task failed with exception
Traceback (most recent call last):
  File "/home/airflow/.local/lib/python3.10/site-packages/airflow/models/taskinstance.py", line 433, in _execute_task
    result = execute_callable(context=context, **execute_callable_kwargs)
  File "/home/airflow/.local/lib/python3.10/site-packages/airflow/operators/python.py", line 199, in execute
    return_value = self.execute_callable()
  File "/home/airflow/.local/lib/python3.10/site-packages/airflow/operators/python.py", line 216, in execute_callable
    return self.python_callable(*self.op_args, **self.op_kwargs)
  File "/opt/airflow/dags/WeatherScripts/spark_Weather.py", line 86, in processData
    query1 = df_exploded.writeStream \
UnboundLocalError: local variable 'df_exploded' referenced before assignment
[2025-04-04T12:52:56.108+0000] {taskinstance.py:1138} INFO - Marking task as FAILED. dag_id=Weather_Proj, task_id=Spark_Processing, execution_date=20250404T125209, start_date=20250404T125250, end_date=20250404T125256
[2025-04-04T12:52:56.122+0000] {standard_task_runner.py:107} ERROR - Failed to execute job 180 for task Spark_Processing (local variable 'df_exploded' referenced before assignment; 3397)
[2025-04-04T12:52:56.157+0000] {local_task_job_runner.py:234} INFO - Task exited with return code 1
[2025-04-04T12:52:56.173+0000] {taskinstance.py:3280} INFO - 0 downstream tasks scheduled from follow-on schedule check
