[2025-04-02T19:44:56.206+0000] {taskinstance.py:1956} INFO - Dependencies all met for dep_context=non-requeueable deps ti=<TaskInstance: Weather_Proj.Produce_data manual__2025-04-02T19:44:50.875615+00:00 [queued]>
[2025-04-02T19:44:56.212+0000] {taskinstance.py:1956} INFO - Dependencies all met for dep_context=requeueable deps ti=<TaskInstance: Weather_Proj.Produce_data manual__2025-04-02T19:44:50.875615+00:00 [queued]>
[2025-04-02T19:44:56.213+0000] {taskinstance.py:2170} INFO - Starting attempt 1 of 1
[2025-04-02T19:44:56.226+0000] {taskinstance.py:2191} INFO - Executing <Task(PythonOperator): Produce_data> on 2025-04-02 19:44:50.875615+00:00
[2025-04-02T19:44:56.234+0000] {clientserver.py:543} INFO - Closing down clientserver connection
[2025-04-02T19:44:56.234+0000] {standard_task_runner.py:60} INFO - Started process 1017 to run task
[2025-04-02T19:44:56.241+0000] {standard_task_runner.py:87} INFO - Running: ['***', 'tasks', 'run', 'Weather_Proj', 'Produce_data', 'manual__2025-04-02T19:44:50.875615+00:00', '--job-id', '5', '--raw', '--subdir', 'DAGS_FOLDER/Project_tasks.py', '--cfg-path', '/tmp/tmpgpq8_37z']
[2025-04-02T19:44:56.243+0000] {standard_task_runner.py:88} INFO - Job 5: Subtask Produce_data
[2025-04-02T19:44:56.283+0000] {task_command.py:423} INFO - Running <TaskInstance: Weather_Proj.Produce_data manual__2025-04-02T19:44:50.875615+00:00 [running]> on host 12651c21963e
[2025-04-02T19:44:56.345+0000] {taskinstance.py:2480} INFO - Exporting env vars: AIRFLOW_CTX_DAG_OWNER='***' AIRFLOW_CTX_DAG_ID='Weather_Proj' AIRFLOW_CTX_TASK_ID='Produce_data' AIRFLOW_CTX_EXECUTION_DATE='2025-04-02T19:44:50.875615+00:00' AIRFLOW_CTX_TRY_NUMBER='1' AIRFLOW_CTX_DAG_RUN_ID='manual__2025-04-02T19:44:50.875615+00:00'
[2025-04-02T19:44:56.346+0000] {taskinstance.py:2698} ERROR - Task failed with exception
Traceback (most recent call last):
  File "/home/airflow/.local/lib/python3.10/site-packages/airflow/models/taskinstance.py", line 433, in _execute_task
    result = execute_callable(context=context, **execute_callable_kwargs)
  File "/home/airflow/.local/lib/python3.10/site-packages/airflow/operators/python.py", line 199, in execute
    return_value = self.execute_callable()
  File "/home/airflow/.local/lib/python3.10/site-packages/airflow/operators/python.py", line 216, in execute_callable
    return self.python_callable(*self.op_args, **self.op_kwargs)
  File "/opt/airflow/dags/WeatherScripts/API_Call.py", line 11, in apiCall
    with open("Egypt.citites_used.txt","r",encoding="utf-8") as f:
FileNotFoundError: [Errno 2] No such file or directory: 'Egypt.citites_used.txt'
[2025-04-02T19:44:56.356+0000] {taskinstance.py:1138} INFO - Marking task as FAILED. dag_id=Weather_Proj, task_id=Produce_data, execution_date=20250402T194450, start_date=20250402T194456, end_date=20250402T194456
[2025-04-02T19:44:56.364+0000] {standard_task_runner.py:107} ERROR - Failed to execute job 5 for task Produce_data ([Errno 2] No such file or directory: 'Egypt.citites_used.txt'; 1017)
[2025-04-02T19:44:56.412+0000] {local_task_job_runner.py:234} INFO - Task exited with return code 1
[2025-04-02T19:44:56.445+0000] {taskinstance.py:3280} INFO - 0 downstream tasks scheduled from follow-on schedule check
