[2025-04-02T20:44:07.878+0000] {taskinstance.py:1956} INFO - Dependencies all met for dep_context=non-requeueable deps ti=<TaskInstance: Weather_Proj.Create_Cassandra_schema scheduled__2025-04-02T20:00:00+00:00 [queued]>
[2025-04-02T20:44:07.885+0000] {taskinstance.py:1956} INFO - Dependencies all met for dep_context=requeueable deps ti=<TaskInstance: Weather_Proj.Create_Cassandra_schema scheduled__2025-04-02T20:00:00+00:00 [queued]>
[2025-04-02T20:44:07.886+0000] {taskinstance.py:2170} INFO - Starting attempt 1 of 1
[2025-04-02T20:44:07.899+0000] {taskinstance.py:2191} INFO - Executing <Task(PythonOperator): Create_Cassandra_schema> on 2025-04-02 20:00:00+00:00
[2025-04-02T20:44:07.904+0000] {clientserver.py:543} INFO - Closing down clientserver connection
[2025-04-02T20:44:07.904+0000] {standard_task_runner.py:60} INFO - Started process 3355 to run task
[2025-04-02T20:44:07.910+0000] {standard_task_runner.py:87} INFO - Running: ['***', 'tasks', 'run', 'Weather_Proj', 'Create_Cassandra_schema', 'scheduled__2025-04-02T20:00:00+00:00', '--job-id', '32', '--raw', '--subdir', 'DAGS_FOLDER/Project_tasks.py', '--cfg-path', '/tmp/tmp5dk4zoly']
[2025-04-02T20:44:07.911+0000] {standard_task_runner.py:88} INFO - Job 32: Subtask Create_Cassandra_schema
[2025-04-02T20:44:07.960+0000] {task_command.py:423} INFO - Running <TaskInstance: Weather_Proj.Create_Cassandra_schema scheduled__2025-04-02T20:00:00+00:00 [running]> on host 34d96960033d
[2025-04-02T20:44:08.038+0000] {taskinstance.py:2480} INFO - Exporting env vars: AIRFLOW_CTX_DAG_OWNER='***' AIRFLOW_CTX_DAG_ID='Weather_Proj' AIRFLOW_CTX_TASK_ID='Create_Cassandra_schema' AIRFLOW_CTX_EXECUTION_DATE='2025-04-02T20:00:00+00:00' AIRFLOW_CTX_TRY_NUMBER='1' AIRFLOW_CTX_DAG_RUN_ID='scheduled__2025-04-02T20:00:00+00:00'
[2025-04-02T20:44:11.426+0000] {taskinstance.py:2698} ERROR - Task failed with exception
Traceback (most recent call last):
  File "/home/airflow/.local/lib/python3.10/site-packages/airflow/models/taskinstance.py", line 433, in _execute_task
    result = execute_callable(context=context, **execute_callable_kwargs)
  File "/home/airflow/.local/lib/python3.10/site-packages/airflow/operators/python.py", line 199, in execute
    return_value = self.execute_callable()
  File "/home/airflow/.local/lib/python3.10/site-packages/airflow/operators/python.py", line 216, in execute_callable
    return self.python_callable(*self.op_args, **self.op_kwargs)
  File "/opt/airflow/dags/WeatherScripts/cassandra_creator.py", line 4, in create_schema
    cluster = Cluster(["cassandra"])  # Use container name
  File "cassandra/cluster.py", line 1231, in cassandra.cluster.Cluster.__init__
cassandra.UnresolvableContactPoints: {}
[2025-04-02T20:44:11.438+0000] {taskinstance.py:1138} INFO - Marking task as FAILED. dag_id=Weather_Proj, task_id=Create_Cassandra_schema, execution_date=20250402T200000, start_date=20250402T204407, end_date=20250402T204411
[2025-04-02T20:44:11.448+0000] {standard_task_runner.py:107} ERROR - Failed to execute job 32 for task Create_Cassandra_schema ({}; 3355)
[2025-04-02T20:44:11.491+0000] {local_task_job_runner.py:234} INFO - Task exited with return code 1
[2025-04-02T20:44:11.520+0000] {taskinstance.py:3280} INFO - 0 downstream tasks scheduled from follow-on schedule check
