[2025-04-02T20:55:06.417+0000] {taskinstance.py:1956} INFO - Dependencies all met for dep_context=non-requeueable deps ti=<TaskInstance: Weather_Proj.Create_Cassandra_schema manual__2025-04-02T20:53:56.692455+00:00 [queued]>
[2025-04-02T20:55:06.424+0000] {taskinstance.py:1956} INFO - Dependencies all met for dep_context=requeueable deps ti=<TaskInstance: Weather_Proj.Create_Cassandra_schema manual__2025-04-02T20:53:56.692455+00:00 [queued]>
[2025-04-02T20:55:06.425+0000] {taskinstance.py:2170} INFO - Starting attempt 1 of 1
[2025-04-02T20:55:06.438+0000] {taskinstance.py:2191} INFO - Executing <Task(PythonOperator): Create_Cassandra_schema> on 2025-04-02 20:53:56.692455+00:00
[2025-04-02T20:55:06.444+0000] {standard_task_runner.py:60} INFO - Started process 4398 to run task
[2025-04-02T20:55:06.444+0000] {clientserver.py:543} INFO - Closing down clientserver connection
[2025-04-02T20:55:06.449+0000] {standard_task_runner.py:87} INFO - Running: ['***', 'tasks', 'run', 'Weather_Proj', 'Create_Cassandra_schema', 'manual__2025-04-02T20:53:56.692455+00:00', '--job-id', '35', '--raw', '--subdir', 'DAGS_FOLDER/Project_tasks.py', '--cfg-path', '/tmp/tmp6uqo8oub']
[2025-04-02T20:55:06.449+0000] {standard_task_runner.py:88} INFO - Job 35: Subtask Create_Cassandra_schema
[2025-04-02T20:55:06.491+0000] {task_command.py:423} INFO - Running <TaskInstance: Weather_Proj.Create_Cassandra_schema manual__2025-04-02T20:53:56.692455+00:00 [running]> on host 34d96960033d
[2025-04-02T20:55:06.556+0000] {taskinstance.py:2480} INFO - Exporting env vars: AIRFLOW_CTX_DAG_OWNER='***' AIRFLOW_CTX_DAG_ID='Weather_Proj' AIRFLOW_CTX_TASK_ID='Create_Cassandra_schema' AIRFLOW_CTX_EXECUTION_DATE='2025-04-02T20:53:56.692455+00:00' AIRFLOW_CTX_TRY_NUMBER='1' AIRFLOW_CTX_DAG_RUN_ID='manual__2025-04-02T20:53:56.692455+00:00'
[2025-04-02T20:55:06.561+0000] {cassandra_creator.py:4} WARNING - Cluster.__init__ called with contact_points specified, but no load_balancing_policy. In the next major version, this will raise an error; please specify a load-balancing policy. (contact_points = ['172.19.0.2'], lbp = None)
[2025-04-02T20:55:11.570+0000] {cassandra_creator.py:5} WARNING - [control connection] Error connecting to 172.19.0.2:9042:
Traceback (most recent call last):
  File "cassandra/cluster.py", line 3577, in cassandra.cluster.ControlConnection._reconnect_internal
  File "cassandra/cluster.py", line 3599, in cassandra.cluster.ControlConnection._try_connect
  File "cassandra/cluster.py", line 1670, in cassandra.cluster.Cluster.connection_factory
  File "cassandra/connection.py", line 846, in cassandra.connection.Connection.factory
  File "/home/airflow/.local/lib/python3.10/site-packages/cassandra/io/libevreactor.py", line 267, in __init__
    self._connect_socket()
  File "cassandra/connection.py", line 951, in cassandra.connection.Connection._connect_socket
OSError: [Errno None] Tried connecting to [('172.19.0.2', 9042)]. Last error: timed out
[2025-04-02T20:55:11.573+0000] {cassandra_creator.py:5} ERROR - Control connection failed to connect, shutting down Cluster:
Traceback (most recent call last):
  File "cassandra/cluster.py", line 1740, in cassandra.cluster.Cluster.connect
  File "cassandra/cluster.py", line 3543, in cassandra.cluster.ControlConnection.connect
  File "cassandra/cluster.py", line 3588, in cassandra.cluster.ControlConnection._reconnect_internal
cassandra.cluster.NoHostAvailable: ('Unable to connect to any servers', {'172.19.0.2:9042': OSError(None, "Tried connecting to [('172.19.0.2', 9042)]. Last error: timed out")})
[2025-04-02T20:55:11.574+0000] {taskinstance.py:2698} ERROR - Task failed with exception
Traceback (most recent call last):
  File "/home/airflow/.local/lib/python3.10/site-packages/airflow/models/taskinstance.py", line 433, in _execute_task
    result = execute_callable(context=context, **execute_callable_kwargs)
  File "/home/airflow/.local/lib/python3.10/site-packages/airflow/operators/python.py", line 199, in execute
    return_value = self.execute_callable()
  File "/home/airflow/.local/lib/python3.10/site-packages/airflow/operators/python.py", line 216, in execute_callable
    return self.python_callable(*self.op_args, **self.op_kwargs)
  File "/opt/airflow/dags/WeatherScripts/cassandra_creator.py", line 5, in create_schema
    session = cluster.connect()
  File "cassandra/cluster.py", line 1717, in cassandra.cluster.Cluster.connect
  File "cassandra/cluster.py", line 1753, in cassandra.cluster.Cluster.connect
  File "cassandra/cluster.py", line 1740, in cassandra.cluster.Cluster.connect
  File "cassandra/cluster.py", line 3543, in cassandra.cluster.ControlConnection.connect
  File "cassandra/cluster.py", line 3588, in cassandra.cluster.ControlConnection._reconnect_internal
cassandra.cluster.NoHostAvailable: ('Unable to connect to any servers', {'172.19.0.2:9042': OSError(None, "Tried connecting to [('172.19.0.2', 9042)]. Last error: timed out")})
[2025-04-02T20:55:11.585+0000] {taskinstance.py:1138} INFO - Marking task as FAILED. dag_id=Weather_Proj, task_id=Create_Cassandra_schema, execution_date=20250402T205356, start_date=20250402T205506, end_date=20250402T205511
[2025-04-02T20:55:11.597+0000] {standard_task_runner.py:107} ERROR - Failed to execute job 35 for task Create_Cassandra_schema (('Unable to connect to any servers', {'172.19.0.2:9042': OSError(None, "Tried connecting to [('172.19.0.2', 9042)]. Last error: timed out")}); 4398)
[2025-04-02T20:55:11.629+0000] {local_task_job_runner.py:234} INFO - Task exited with return code 1
[2025-04-02T20:55:11.648+0000] {taskinstance.py:3280} INFO - 0 downstream tasks scheduled from follow-on schedule check
